<?xml version="1.0" encoding="utf-8"?>
<!-- This URDF was automatically created by SolidWorks to URDF Exporter! Originally created by Stephen Brawner (brawner@gmail.com) 
     Commit Version: 1.6.0-1-g15f4949  Build Version: 1.6.7594.29634
     For more information, please see http://wiki.ros.org/sw_urdf_exporter -->
<robot
  name="ASSY_phantom_urdf">
  <link
    name="reference_plate">
    <inertial>
      <origin
        xyz="-2.29571090240976E-19 -7.6138559525102E-19 -0.005"
        rpy="0 0 0" />
      <mass
        value="0.0695305500046139" />
      <inertia
        ixx="1.46054192066062E-05"
        ixy="3.7521509506977E-38"
        ixz="0"
        iyy="0.000145973966303231"
        iyz="3.15291138410029E-39"
        izz="0.00015942054300976" />
    </inertial>
    <visual>
      <origin
        xyz="0 0 0"
        rpy="0 0 0" />
      <geometry>
        <mesh
          filename="package://ASSY_phantom_urdf/meshes/reference_plate.STL" />
      </geometry>
      <material
        name="">
        <color
          rgba="0.792156862745098 0.819607843137255 0.933333333333333 1" />
      </material>
    </visual>
    <collision>
      <origin
        xyz="0 0 0"
        rpy="0 0 0" />
      <geometry>
        <mesh
          filename="package://ASSY_phantom_urdf/meshes/reference_plate.STL" />
      </geometry>
    </collision>
  </link>
  <link
    name="torso">
    <inertial>
      <origin
        xyz="-4.20026365259337E-08 0.0191077517790398 -0.000857766902298628"
        rpy="0 0 0" />
      <mass
        value="0.361460112918338" />
      <inertia
        ixx="0.000451447699694477"
        ixy="1.05927447589073E-11"
        ixz="8.0139973020819E-13"
        iyy="0.000602965438079502"
        iyz="-7.25588466219997E-09"
        izz="0.00020011493739623" />
    </inertial>
    <visual>
      <origin
        xyz="0 0 0"
        rpy="0 0 0" />
      <geometry>
        <mesh
          filename="package://ASSY_phantom_urdf/meshes/torso.STL" />
      </geometry>
      <material
        name="">
        <color
          rgba="0.792156862745098 0.819607843137255 0.933333333333333 1" />
      </material>
    </visual>
    <collision>
      <origin
        xyz="0 0 0"
        rpy="0 0 0" />
      <geometry>
        <mesh
          filename="package://ASSY_phantom_urdf/meshes/torso.STL" />
      </geometry>
    </collision>
  </link>
  <joint
    name="ref_to_torso_joint"
    type="continuous">
    <origin
      xyz="0 0 0"
      rpy="0 -1.5708 0" />
    <parent
      link="reference_plate" />
    <child
      link="torso" />
    <axis
      xyz="0 1 0" />
  </joint>
  <link
    name="LF_thigh">
    <inertial>
      <origin
        xyz="0.000962648433085952 0.0194026504100212 -0.0259911487205287"
        rpy="0 0 0" />
      <mass
        value="0.0187184822855238" />
      <inertia
        ixx="4.58328035716512E-06"
        ixy="1.45278176785183E-12"
        ixz="8.99636334395285E-11"
        iyy="4.58328060295336E-06"
        iyz="-9.54262640564057E-11"
        izz="5.84140443768982E-06" />
    </inertial>
    <visual>
      <origin
        xyz="0 0 0"
        rpy="0 0 0" />
      <geometry>
        <mesh
          filename="package://ASSY_phantom_urdf/meshes/LF_thigh.STL" />
      </geometry>
      <material
        name="">
        <color
          rgba="0.792156862745098 0.819607843137255 0.933333333333333 1" />
      </material>
    </visual>
    <collision>
      <origin
        xyz="0 0 0"
        rpy="0 0 0" />
      <geometry>
        <mesh
          filename="package://ASSY_phantom_urdf/meshes/LF_thigh.STL" />
      </geometry>
    </collision>
  </link>
  <joint
    name="LF1"
    type="continuous">
    <origin
      xyz="0.06091 0 0.12191"
      rpy="3.1416 -0.7854 -3.1416" />
    <parent
      link="torso" />
    <child
      link="LF_thigh" />
    <axis
      xyz="0 1 0" />
  </joint>
  <link
    name="LF_calf">
    <inertial>
      <origin
        xyz="0.000736289101338099 0.0205456005926864 -0.008758027531787"
        rpy="0 0 0" />
      <mass
        value="0.0551626378991535" />
      <inertia
        ixx="1.16899614361583E-05"
        ixy="-1.79508008437842E-07"
        ixz="6.53555214939164E-08"
        iyy="1.13260384080131E-05"
        iyz="1.84901035804858E-06"
        izz="1.4690400027612E-05" />
    </inertial>
    <visual>
      <origin
        xyz="0 0 0"
        rpy="0 0 0" />
      <geometry>
        <mesh
          filename="package://ASSY_phantom_urdf/meshes/LF_calf.STL" />
      </geometry>
      <material
        name="">
        <color
          rgba="0.792156862745098 0.819607843137255 0.933333333333333 1" />
      </material>
    </visual>
    <collision>
      <origin
        xyz="0 0 0"
        rpy="0 0 0" />
      <geometry>
        <mesh
          filename="package://ASSY_phantom_urdf/meshes/LF_calf.STL" />
      </geometry>
    </collision>
  </link>
  <joint
    name="LF2"
    type="continuous">
    <origin
      xyz="0 0.01844 -0.052"
      rpy="-0.428439870509635 0 0" />
    <parent
      link="LF_thigh" />
    <child
      link="LF_calf" />
    <axis
      xyz="1 0 0" />
  </joint>
  <link
    name="LF_foot">
    <inertial>
      <origin
        xyz="0.000412462660724804 -0.0333551606347992 -0.01867518046554"
        rpy="0 0 0" />
      <mass
        value="0.0659803620597775" />
      <inertia
        ixx="2.59560666919155E-05"
        ixy="9.83540703702039E-08"
        ixz="1.637483932444E-07"
        iyy="1.25102982671869E-05"
        iyz="-2.00891186302198E-06"
        izz="2.36167186288937E-05" />
    </inertial>
    <visual>
      <origin
        xyz="0 0 0"
        rpy="0 0 0" />
      <geometry>
        <mesh
          filename="package://ASSY_phantom_urdf/meshes/LF_foot.STL" />
      </geometry>
      <material
        name="">
        <color
          rgba="0.792156862745098 0.819607843137255 0.933333333333333 1" />
      </material>
    </visual>
    <collision>
      <origin
        xyz="0 0 0"
        rpy="0 0 0" />
      <geometry>
        <mesh
          filename="package://ASSY_phantom_urdf/meshes/LF_foot.STL" />
      </geometry>
    </collision>
  </link>
  <joint
    name="LF3"
    type="continuous">
    <origin
      xyz="0 0.0552704102679548 -0.0361826753434916"
      rpy="0.396828297419917 0 0" />
    <parent
      link="LF_calf" />
    <child
      link="LF_foot" />
    <axis
      xyz="1 0 0" />
  </joint>
  <link
    name="LM_thigh">
    <inertial>
      <origin
        xyz="0.000962652251555589 0.0194026522338854 -0.0259911994400861"
        rpy="0 0 0" />
      <mass
        value="0.0187184853256144" />
      <inertia
        ixx="4.58327757136495E-06"
        ixy="1.61257794818298E-12"
        ixz="9.21329265902019E-11"
        iyy="4.58327757136493E-06"
        iyz="-9.21318961790252E-11"
        izz="5.84140473916597E-06" />
    </inertial>
    <visual>
      <origin
        xyz="0 0 0"
        rpy="0 0 0" />
      <geometry>
        <mesh
          filename="package://ASSY_phantom_urdf/meshes/LM_thigh.STL" />
      </geometry>
      <material
        name="">
        <color
          rgba="0.792156862745098 0.819607843137255 0.933333333333333 1" />
      </material>
    </visual>
    <collision>
      <origin
        xyz="0 0 0"
        rpy="0 0 0" />
      <geometry>
        <mesh
          filename="package://ASSY_phantom_urdf/meshes/LM_thigh.STL" />
      </geometry>
    </collision>
  </link>
  <joint
    name="LM1"
    type="continuous">
    <origin
      xyz="0.1035 0 0"
      rpy="3.14159265358979 -1.5707963267949 0" />
    <parent
      link="torso" />
    <child
      link="LM_thigh" />
    <axis
      xyz="0 1 0" />
  </joint>
  <link
    name="LM_calf">
    <inertial>
      <origin
        xyz="0.000736290749245126 0.0205456037859605 -0.00875803140989759"
        rpy="0 0 0" />
      <mass
        value="0.0551626363009457" />
      <inertia
        ixx="1.16899658431903E-05"
        ixy="-1.79507647092078E-07"
        ixz="6.53549457968838E-08"
        iyy="1.1326041676615E-05"
        iyz="1.84901209582534E-06"
        izz="1.46904010239772E-05" />
    </inertial>
    <visual>
      <origin
        xyz="0 0 0"
        rpy="0 0 0" />
      <geometry>
        <mesh
          filename="package://ASSY_phantom_urdf/meshes/LM_calf.STL" />
      </geometry>
      <material
        name="">
        <color
          rgba="0.792156862745098 0.819607843137255 0.933333333333333 1" />
      </material>
    </visual>
    <collision>
      <origin
        xyz="0 0 0"
        rpy="0 0 0" />
      <geometry>
        <mesh
          filename="package://ASSY_phantom_urdf/meshes/LM_calf.STL" />
      </geometry>
    </collision>
  </link>
  <joint
    name="LM2"
    type="continuous">
    <origin
      xyz="0 0.01844 -0.052"
      rpy="-0.428439870509635 0 0" />
    <parent
      link="LM_thigh" />
    <child
      link="LM_calf" />
    <axis
      xyz="1 0 0" />
  </joint>
  <link
    name="LM_foot">
    <inertial>
      <origin
        xyz="0.000412462344737784 -0.0333551499088378 -0.0186751759055259"
        rpy="0 0 0" />
      <mass
        value="0.0659803344728989" />
      <inertia
        ixx="2.59560663827908E-05"
        ixy="9.83540777732148E-08"
        ixz="1.63748408217199E-07"
        iyy="1.25102980235315E-05"
        iyz="-2.00891171594794E-06"
        izz="2.36167183432796E-05" />
    </inertial>
    <visual>
      <origin
        xyz="0 0 0"
        rpy="0 0 0" />
      <geometry>
        <mesh
          filename="package://ASSY_phantom_urdf/meshes/LM_foot.STL" />
      </geometry>
      <material
        name="">
        <color
          rgba="0.792156862745098 0.819607843137255 0.933333333333333 1" />
      </material>
    </visual>
    <collision>
      <origin
        xyz="0 0 0"
        rpy="0 0 0" />
      <geometry>
        <mesh
          filename="package://ASSY_phantom_urdf/meshes/LM_foot.STL" />
      </geometry>
    </collision>
  </link>
  <joint
    name="LM3"
    type="continuous">
    <origin
      xyz="0 0.0552704102679549 -0.0361826753434916"
      rpy="0.396828297419917 0 0" />
    <parent
      link="LM_calf" />
    <child
      link="LM_foot" />
    <axis
      xyz="1 0 0" />
  </joint>
  <link
    name="LB_thigh">
    <inertial>
      <origin
        xyz="0.000962648433085966 0.0194026504100212 -0.0259911487205288"
        rpy="0 0 0" />
      <mass
        value="0.0187184822855238" />
      <inertia
        ixx="4.58328035716511E-06"
        ixy="1.45278176907644E-12"
        ixz="8.99636334403755E-11"
        iyy="4.58328060295335E-06"
        iyz="-9.54262640556684E-11"
        izz="5.84140443768982E-06" />
    </inertial>
    <visual>
      <origin
        xyz="0 0 0"
        rpy="0 0 0" />
      <geometry>
        <mesh
          filename="package://ASSY_phantom_urdf/meshes/LB_thigh.STL" />
      </geometry>
      <material
        name="">
        <color
          rgba="0.792156862745098 0.819607843137255 0.933333333333333 1" />
      </material>
    </visual>
    <collision>
      <origin
        xyz="0 0 0"
        rpy="0 0 0" />
      <geometry>
        <mesh
          filename="package://ASSY_phantom_urdf/meshes/LB_thigh.STL" />
      </geometry>
    </collision>
  </link>
  <joint
    name="LB1"
    type="continuous">
    <origin
      xyz="0.0609100775541958 0 -0.121910077554196"
      rpy="0 -0.78539816339745 0" />
    <parent
      link="torso" />
    <child
      link="LB_thigh" />
    <axis
      xyz="0 1 0" />
  </joint>
  <link
    name="LB_calf">
    <inertial>
      <origin
        xyz="0.000736289101338015 0.0205456005926864 -0.00875802753178698"
        rpy="0 0 0" />
      <mass
        value="0.0551626378991534" />
      <inertia
        ixx="1.16899614361583E-05"
        ixy="-1.79508008437838E-07"
        ixz="6.53555214939129E-08"
        iyy="1.1326038408013E-05"
        iyz="1.84901035804858E-06"
        izz="1.46904000276119E-05" />
    </inertial>
    <visual>
      <origin
        xyz="0 0 0"
        rpy="0 0 0" />
      <geometry>
        <mesh
          filename="package://ASSY_phantom_urdf/meshes/LB_calf.STL" />
      </geometry>
      <material
        name="">
        <color
          rgba="0.792156862745098 0.819607843137255 0.933333333333333 1" />
      </material>
    </visual>
    <collision>
      <origin
        xyz="0 0 0"
        rpy="0 0 0" />
      <geometry>
        <mesh
          filename="package://ASSY_phantom_urdf/meshes/LB_calf.STL" />
      </geometry>
    </collision>
  </link>
  <joint
    name="LB2"
    type="continuous">
    <origin
      xyz="0 0.01844 -0.0519999999999999"
      rpy="-0.428439870509635 0 0" />
    <parent
      link="LB_thigh" />
    <child
      link="LB_calf" />
    <axis
      xyz="1 0 0" />
  </joint>
  <link
    name="LB_foot">
    <inertial>
      <origin
        xyz="0.000252462660724595 -0.0333551606347992 -0.0186751804655401"
        rpy="0 0 0" />
      <mass
        value="0.0659803620597775" />
      <inertia
        ixx="2.59560666919155E-05"
        ixy="9.83540703701817E-08"
        ixz="1.63748393244395E-07"
        iyy="1.25102982671869E-05"
        iyz="-2.00891186302197E-06"
        izz="2.36167186288937E-05" />
    </inertial>
    <visual>
      <origin
        xyz="0 0 0"
        rpy="0 0 0" />
      <geometry>
        <mesh
          filename="package://ASSY_phantom_urdf/meshes/LB_foot.STL" />
      </geometry>
      <material
        name="">
        <color
          rgba="0.792156862745098 0.819607843137255 0.933333333333333 1" />
      </material>
    </visual>
    <collision>
      <origin
        xyz="0 0 0"
        rpy="0 0 0" />
      <geometry>
        <mesh
          filename="package://ASSY_phantom_urdf/meshes/LB_foot.STL" />
      </geometry>
    </collision>
  </link>
  <joint
    name="LB3"
    type="continuous">
    <origin
      xyz="0 0.0552704102679549 -0.0361826753434916"
      rpy="0.396828297419918 0 0" />
    <parent
      link="LB_calf" />
    <child
      link="LB_foot" />
    <axis
      xyz="1 0 0" />
  </joint>
  <link
    name="RF_thigh">
    <inertial>
      <origin
        xyz="0.0194027231911689 -0.000962720771382118 0.0260087651240974"
        rpy="0 0 0" />
      <mass
        value="0.018718799941622" />
      <inertia
        ixx="4.58336747949757E-06"
        ixy="-1.38095725082975E-11"
        ixz="1.50188775489789E-10"
        iyy="4.5833671326977E-06"
        iyz="1.46826574783467E-10"
        izz="5.84152341451724E-06" />
    </inertial>
    <visual>
      <origin
        xyz="0 0 0"
        rpy="0 0 0" />
      <geometry>
        <mesh
          filename="package://ASSY_phantom_urdf/meshes/RF_thigh.STL" />
      </geometry>
      <material
        name="">
        <color
          rgba="0.792156862745098 0.819607843137255 0.933333333333333 1" />
      </material>
    </visual>
    <collision>
      <origin
        xyz="0 0 0"
        rpy="0 0 0" />
      <geometry>
        <mesh
          filename="package://ASSY_phantom_urdf/meshes/RF_thigh.STL" />
      </geometry>
    </collision>
  </link>
  <joint
    name="RF1"
    type="continuous">
    <origin
      xyz="-0.0609100775541958 0 0.121910077554196"
      rpy="-0.785398163397452 0 1.5707963267949" />
    <parent
      link="torso" />
    <child
      link="RF_thigh" />
    <axis
      xyz="1 0 0" />
  </joint>
  <link
    name="RF_calf">
    <inertial>
      <origin
        xyz="0.000736290426934662 0.0205456831764225 0.00875806720801461"
        rpy="0 0 0" />
      <mass
        value="0.0551628381773646" />
      <inertia
        ixx="1.16899750551211E-05"
        ixy="-1.79504880014545E-07"
        ixz="-6.53847557908524E-08"
        iyy="1.13260997211582E-05"
        iyz="-1.84902525857226E-06"
        izz="1.46904739827742E-05" />
    </inertial>
    <visual>
      <origin
        xyz="0 0 0"
        rpy="0 0 0" />
      <geometry>
        <mesh
          filename="package://ASSY_phantom_urdf/meshes/RF_calf.STL" />
      </geometry>
      <material
        name="">
        <color
          rgba="0.792156862745098 0.819607843137255 0.933333333333333 1" />
      </material>
    </visual>
    <collision>
      <origin
        xyz="0 0 0"
        rpy="0 0 0" />
      <geometry>
        <mesh
          filename="package://ASSY_phantom_urdf/meshes/RF_calf.STL" />
      </geometry>
    </collision>
  </link>
  <joint
    name="RF2"
    type="continuous">
    <origin
      xyz="0.0184400000000001 0 0.0520000000000002"
      rpy="0.428439870509634 0 -1.5707963267949" />
    <parent
      link="RF_thigh" />
    <child
      link="RF_calf" />
    <axis
      xyz="1 0 0" />
  </joint>
  <link
    name="RF_foot">
    <inertial>
      <origin
        xyz="0.000412444970048088 -0.033355131524438 0.0186751748473197"
        rpy="0 0 0" />
      <mass
        value="0.0659804422526083" />
      <inertia
        ixx="2.59560574979232E-05"
        ixy="9.83509696596042E-08"
        ixz="-1.6374496689321E-07"
        iyy="1.25103110267222E-05"
        iyz="2.00890900968632E-06"
        izz="2.36167344837691E-05" />
    </inertial>
    <visual>
      <origin
        xyz="0 0 0"
        rpy="0 0 0" />
      <geometry>
        <mesh
          filename="package://ASSY_phantom_urdf/meshes/RF_foot.STL" />
      </geometry>
      <material
        name="">
        <color
          rgba="0.792156862745098 0.819607843137255 0.933333333333333 1" />
      </material>
    </visual>
    <collision>
      <origin
        xyz="0 0 0"
        rpy="0 0 0" />
      <geometry>
        <mesh
          filename="package://ASSY_phantom_urdf/meshes/RF_foot.STL" />
      </geometry>
    </collision>
  </link>
  <joint
    name="RF3"
    type="continuous">
    <origin
      xyz="0 0.0627573500923168 0.0390014928378291"
      rpy="-0.396828297419917 0 0" />
    <parent
      link="RF_calf" />
    <child
      link="RF_foot" />
    <axis
      xyz="1 0 0" />
  </joint>
  <link
    name="RM_thigh">
    <inertial>
      <origin
        xyz="0.0194027237249261 -0.000962723742565761 0.0260088003580918"
        rpy="0 0 0" />
      <mass
        value="0.0187188019506362" />
      <inertia
        ixx="4.58336504964395E-06"
        ixy="-1.38919554681972E-11"
        ixz="1.48345216925798E-10"
        iyy="4.58336504964394E-06"
        iyz="1.48346245086798E-10"
        izz="5.84152380154399E-06" />
    </inertial>
    <visual>
      <origin
        xyz="0 0 0"
        rpy="0 0 0" />
      <geometry>
        <mesh
          filename="package://ASSY_phantom_urdf/meshes/RM_thigh.STL" />
      </geometry>
      <material
        name="">
        <color
          rgba="0.792156862745098 0.819607843137255 0.933333333333333 1" />
      </material>
    </visual>
    <collision>
      <origin
        xyz="0 0 0"
        rpy="0 0 0" />
      <geometry>
        <mesh
          filename="package://ASSY_phantom_urdf/meshes/RM_thigh.STL" />
      </geometry>
    </collision>
  </link>
  <joint
    name="RM1"
    type="continuous">
    <origin
      xyz="-0.1035 0 0"
      rpy="-1.5707963267949 0 1.5707963267949" />
    <parent
      link="torso" />
    <child
      link="RM_thigh" />
    <axis
      xyz="1 0 0" />
  </joint>
  <link
    name="RM_calf">
    <inertial>
      <origin
        xyz="0.000736291327771293 0.0205456846827271 0.00875806984040992"
        rpy="0 0 0" />
      <mass
        value="0.0551628383375633" />
      <inertia
        ixx="1.16899783369346E-05"
        ixy="-1.79504377078489E-07"
        ixz="-6.53837296757084E-08"
        iyy="1.13261026243006E-05"
        iyz="-1.84902632673917E-06"
        izz="1.46904744145783E-05" />
    </inertial>
    <visual>
      <origin
        xyz="0 0 0"
        rpy="0 0 0" />
      <geometry>
        <mesh
          filename="package://ASSY_phantom_urdf/meshes/RM_calf.STL" />
      </geometry>
      <material
        name="">
        <color
          rgba="0.792156862745098 0.819607843137255 0.933333333333333 1" />
      </material>
    </visual>
    <collision>
      <origin
        xyz="0 0 0"
        rpy="0 0 0" />
      <geometry>
        <mesh
          filename="package://ASSY_phantom_urdf/meshes/RM_calf.STL" />
      </geometry>
    </collision>
  </link>
  <joint
    name="RM2"
    type="continuous">
    <origin
      xyz="0.0184400000000001 0 0.0520000000000001"
      rpy="0.428439870509635 0 -1.5707963267949" />
    <parent
      link="RM_thigh" />
    <child
      link="RM_calf" />
    <axis
      xyz="1 0 0" />
  </joint>
  <link
    name="RM_foot">
    <inertial>
      <origin
        xyz="0.000412444394053668 -0.033355120047462 0.0186751702294503"
        rpy="0 0 0" />
      <mass
        value="0.0659804165929113" />
      <inertia
        ixx="2.59560571642623E-05"
        ixy="9.83509674568297E-08"
        ixz="-1.63744970498219E-07"
        iyy="1.25103108194909E-05"
        iyz="2.00890881392885E-06"
        izz="2.36167342109956E-05" />
    </inertial>
    <visual>
      <origin
        xyz="0 0 0"
        rpy="0 0 0" />
      <geometry>
        <mesh
          filename="package://ASSY_phantom_urdf/meshes/RM_foot.STL" />
      </geometry>
      <material
        name="">
        <color
          rgba="0.792156862745098 0.819607843137255 0.933333333333333 1" />
      </material>
    </visual>
    <collision>
      <origin
        xyz="0 0 0"
        rpy="0 0 0" />
      <geometry>
        <mesh
          filename="package://ASSY_phantom_urdf/meshes/RM_foot.STL" />
      </geometry>
    </collision>
  </link>
  <joint
    name="RM3"
    type="continuous">
    <origin
      xyz="0 0.0552704102679548 0.0361826753434916"
      rpy="-0.396828297419917 0 0" />
    <parent
      link="RM_calf" />
    <child
      link="RM_foot" />
    <axis
      xyz="1 0 0" />
  </joint>
  <link
    name="RB_thigh">
    <inertial>
      <origin
        xyz="0.0194027231911689 -0.000962720771382153 0.0260087651240973"
        rpy="0 0 0" />
      <mass
        value="0.0187187999416221" />
      <inertia
        ixx="4.58336747949758E-06"
        ixy="-1.38095725066893E-11"
        ixz="1.50188775486848E-10"
        iyy="4.58336713269771E-06"
        iyz="1.46826574782832E-10"
        izz="5.84152341451725E-06" />
    </inertial>
    <visual>
      <origin
        xyz="0 0 0"
        rpy="0 0 0" />
      <geometry>
        <mesh
          filename="package://ASSY_phantom_urdf/meshes/RB_thigh.STL" />
      </geometry>
      <material
        name="">
        <color
          rgba="0.792156862745098 0.819607843137255 0.933333333333333 1" />
      </material>
    </visual>
    <collision>
      <origin
        xyz="0 0 0"
        rpy="0 0 0" />
      <geometry>
        <mesh
          filename="package://ASSY_phantom_urdf/meshes/RB_thigh.STL" />
      </geometry>
    </collision>
  </link>
  <joint
    name="RB1"
    type="continuous">
    <origin
      xyz="-0.0609100775541957 0 -0.121910077554196"
      rpy="-2.35619449019234 0 1.5707963267949" />
    <parent
      link="torso" />
    <child
      link="RB_thigh" />
    <axis
      xyz="1 0 0" />
  </joint>
  <link
    name="RB_calf">
    <inertial>
      <origin
        xyz="0.000736290426934474 0.0205456831764226 0.00875806720801464"
        rpy="0 0 0" />
      <mass
        value="0.0551628381773647" />
      <inertia
        ixx="1.16899750551211E-05"
        ixy="-1.79504880014546E-07"
        ixz="-6.53847557908654E-08"
        iyy="1.13260997211582E-05"
        iyz="-1.84902525857226E-06"
        izz="1.46904739827743E-05" />
    </inertial>
    <visual>
      <origin
        xyz="0 0 0"
        rpy="0 0 0" />
      <geometry>
        <mesh
          filename="package://ASSY_phantom_urdf/meshes/RB_calf.STL" />
      </geometry>
      <material
        name="">
        <color
          rgba="0.792156862745098 0.819607843137255 0.933333333333333 1" />
      </material>
    </visual>
    <collision>
      <origin
        xyz="0 0 0"
        rpy="0 0 0" />
      <geometry>
        <mesh
          filename="package://ASSY_phantom_urdf/meshes/RB_calf.STL" />
      </geometry>
    </collision>
  </link>
  <joint
    name="RB2"
    type="continuous">
    <origin
      xyz="0.01844 0 0.052"
      rpy="0.428439870509635 0 -1.5707963267949" />
    <parent
      link="RB_thigh" />
    <child
      link="RB_calf" />
    <axis
      xyz="1 0 0" />
  </joint>
  <link
    name="RB_foot">
    <inertial>
      <origin
        xyz="0.000412444970047492 -0.0333551315244381 0.0186751748473198"
        rpy="0 0 0" />
      <mass
        value="0.0659804422526083" />
      <inertia
        ixx="2.59560574979232E-05"
        ixy="9.8350969659576E-08"
        ixz="-1.63744966893196E-07"
        iyy="1.25103110267222E-05"
        iyz="2.00890900968631E-06"
        izz="2.36167344837691E-05" />
    </inertial>
    <visual>
      <origin
        xyz="0 0 0"
        rpy="0 0 0" />
      <geometry>
        <mesh
          filename="package://ASSY_phantom_urdf/meshes/RB_foot.STL" />
      </geometry>
      <material
        name="">
        <color
          rgba="0.792156862745098 0.819607843137255 0.933333333333333 1" />
      </material>
    </visual>
    <collision>
      <origin
        xyz="0 0 0"
        rpy="0 0 0" />
      <geometry>
        <mesh
          filename="package://ASSY_phantom_urdf/meshes/RB_foot.STL" />
      </geometry>
    </collision>
  </link>
  <joint
    name="RB3"
    type="continuous">
    <origin
      xyz="0 0.055270410267955 0.0361826753434918"
      rpy="-0.396828297419917 0 0" />
    <parent
      link="RB_calf" />
    <child
      link="RB_foot" />
    <axis
      xyz="1 0 0" />
  </joint>
</robot>