<?xml version="1.0" encoding="utf-8"?>
<!-- This URDF was automatically created by SolidWorks to URDF Exporter! Originally created by Stephen Brawner (brawner@gmail.com) 
     Commit Version: 1.6.0-1-g15f4949  Build Version: 1.6.7594.29634
     For more information, please see http://wiki.ros.org/sw_urdf_exporter -->
<robot
  name="ASSY_phantom_urdf">
  <link
    name="torso">
    <inertial>
      <origin
        xyz="-2.30151070338156E-15 0.0191096478900804 -0.000877331766132126"
        rpy="0 0 0" />
      <mass
        value="0.360578160137745" />
      <inertia
        ixx="0.000451442317322487"
        ixy="2.75765891563792E-16"
        ixz="-2.06259455328211E-08"
        iyy="0.000602964001085919"
        iyz="-3.70353956864519E-11"
        izz="0.000200109814370711" />
    </inertial>
    <visual>
      <origin
        xyz="0 0 0"
        rpy="0 0 0" />
      <geometry>
        <mesh
          filename="package://ASSY_phantom_urdf/meshes/torso.STL" />
      </geometry>
      <material
        name="">
        <color
          rgba="0.752941176470588 0.752941176470588 0.752941176470588 1" />
      </material>
    </visual>
    <collision>
      <origin
        xyz="0 0 0"
        rpy="0 0 0" />
      <geometry>
        <mesh
          filename="package://ASSY_phantom_urdf/meshes/torso.STL" />
      </geometry>
    </collision>
  </link>
  <link
    name="LF_thigh">
    <inertial>
      <origin
        xyz="-0.0194026504263946 0.000962648415416018 -0.0260087497830562"
        rpy="0 0 0" />
      <mass
        value="0.0187184822855231" />
      <inertia
        ixx="4.58328060295335E-06"
        ixy="-1.45214380627895E-12"
        ixz="9.54272944662849E-11"
        iyy="4.58328035716507E-06"
        iyz="8.99626362020169E-11"
        izz="5.84140443768987E-06" />
    </inertial>
    <visual>
      <origin
        xyz="0 0 0"
        rpy="0 0 0" />
      <geometry>
        <mesh
          filename="package://ASSY_phantom_urdf/meshes/LF_thigh.STL" />
      </geometry>
      <material
        name="">
        <color
          rgba="0.752941176470588 0.752941176470588 0.752941176470588 1" />
      </material>
    </visual>
    <collision>
      <origin
        xyz="0 0 0"
        rpy="0 0 0" />
      <geometry>
        <mesh
          filename="package://ASSY_phantom_urdf/meshes/LF_thigh.STL" />
      </geometry>
    </collision>
  </link>
  <joint
    name="LF1"
    type="revolute">
    <origin
      xyz="0.06091 0 0.12191"
      rpy="2.3562 0 -1.5708" />
    <parent
      link="torso" />
    <child
      link="LF_thigh" />
    <axis
      xyz="1 0 0" />
    <limit
      lower="-5.236"
      upper="5.236"
      effort="0"
      velocity="0" />
  </joint>
  <link
    name="LF_calf">
    <inertial>
      <origin
        xyz="0.00102679192340011 -0.0223107697760035 -0.000736289104139684"
        rpy="0 0 0" />
      <mass
        value="0.0551626378910084" />
      <inertia
        ixx="1.54903467359071E-05"
        ixy="2.95997531578755E-07"
        ixz="-1.48897181529189E-09"
        iyy="1.05260916908926E-05"
        iyz="-1.91029456445053E-07"
        izz="1.16899614331516E-05" />
    </inertial>
    <visual>
      <origin
        xyz="0 0 0"
        rpy="0 0 0" />
      <geometry>
        <mesh
          filename="package://ASSY_phantom_urdf/meshes/LF_calf.STL" />
      </geometry>
      <material
        name="">
        <color
          rgba="0.752941176470588 0.752941176470588 0.752941176470588 1" />
      </material>
    </visual>
    <collision>
      <origin
        xyz="0 0 0"
        rpy="0 0 0" />
      <geometry>
        <mesh
          filename="package://ASSY_phantom_urdf/meshes/LF_calf.STL" />
      </geometry>
    </collision>
  </link>
  <joint
    name="LF2"
    type="revolute">
    <origin
      xyz="-0.01844 0 -0.052"
      rpy="1.5708 0.7854 0" />
    <parent
      link="LF_thigh" />
    <child
      link="LF_calf" />
    <axis
      xyz="0 0 1" />
    <limit
      lower="-5.236"
      upper="5.236"
      effort="0"
      velocity="0" />
  </joint>
  <link
    name="LF_foot">
    <inertial>
      <origin
        xyz="0.0189834041321391 -0.0332649280290424 -0.000415814389983254"
        rpy="0 0 0" />
      <mass
        value="0.0652326466286266" />
      <inertia
        ixx="1.73083837683577E-05"
        ixy="5.85844793814886E-06"
        ixz="-1.49998074541932E-09"
        iyy="1.87949439630519E-05"
        iyz="-1.91009991926181E-07"
        izz="2.59541244072092E-05" />
    </inertial>
    <visual>
      <origin
        xyz="0 0 0"
        rpy="0 0 0" />
      <geometry>
        <mesh
          filename="package://ASSY_phantom_urdf/meshes/LF_foot.STL" />
      </geometry>
      <material
        name="">
        <color
          rgba="0.752941176470588 0.752941176470588 0.752941176470588 1" />
      </material>
    </visual>
    <collision>
      <origin
        xyz="0 0 0"
        rpy="0 0 0" />
      <geometry>
        <mesh
          filename="package://ASSY_phantom_urdf/meshes/LF_foot.STL" />
      </geometry>
    </collision>
  </link>
  <joint
    name="LF3"
    type="revolute">
    <origin
      xyz="0.014589 -0.06443 0"
      rpy="0 0 1.3658" />
    <parent
      link="LF_calf" />
    <child
      link="LF_foot" />
    <axis
      xyz="0 0 1" />
    <limit
      lower="-5.236"
      upper="5.236"
      effort="0"
      velocity="0" />
  </joint>
  <link
    name="LM_thigh">
    <inertial>
      <origin
        xyz="-0.0194026522515557 0.000962652233885657 -0.0260088005599141"
        rpy="0 0 0" />
      <mass
        value="0.0187184853256138" />
      <inertia
        ixx="4.5832775713649E-06"
        ixy="-1.61257795921829E-12"
        ixz="9.21329265913855E-11"
        iyy="4.5832775713649E-06"
        iyz="9.21318962015843E-11"
        izz="5.84140473916601E-06" />
    </inertial>
    <visual>
      <origin
        xyz="0 0 0"
        rpy="0 0 0" />
      <geometry>
        <mesh
          filename="package://ASSY_phantom_urdf/meshes/LM_thigh.STL" />
      </geometry>
      <material
        name="">
        <color
          rgba="0.752941176470588 0.752941176470588 0.752941176470588 1" />
      </material>
    </visual>
    <collision>
      <origin
        xyz="0 0 0"
        rpy="0 0 0" />
      <geometry>
        <mesh
          filename="package://ASSY_phantom_urdf/meshes/LM_thigh.STL" />
      </geometry>
    </collision>
  </link>
  <joint
    name="LM1"
    type="revolute">
    <origin
      xyz="0.1035 0 0"
      rpy="1.5708 0 -1.5708" />
    <parent
      link="torso" />
    <child
      link="LM_thigh" />
    <axis
      xyz="1 0 0" />
    <limit
      lower="-5.236"
      upper="5.236"
      effort="0"
      velocity="0" />
  </joint>
  <link
    name="LM_calf">
    <inertial>
      <origin
        xyz="0.00102679444128451 -0.0223107741231447 -0.000736290752046597"
        rpy="0 0 0" />
      <mass
        value="0.055162636292801" />
      <inertia
        ixx="1.54903491476744E-05"
        ixy="2.95999588980334E-07"
        ixz="-1.48938499726855E-09"
        iyy="1.05260935442026E-05"
        iyz="-1.91028916676631E-07"
        izz="1.16899658402934E-05" />
    </inertial>
    <visual>
      <origin
        xyz="0 0 0"
        rpy="0 0 0" />
      <geometry>
        <mesh
          filename="package://ASSY_phantom_urdf/meshes/LM_calf.STL" />
      </geometry>
      <material
        name="">
        <color
          rgba="0.752941176470588 0.752941176470588 0.752941176470588 1" />
      </material>
    </visual>
    <collision>
      <origin
        xyz="0 0 0"
        rpy="0 0 0" />
      <geometry>
        <mesh
          filename="package://ASSY_phantom_urdf/meshes/LM_calf.STL" />
      </geometry>
    </collision>
  </link>
  <joint
    name="LM2"
    type="revolute">
    <origin
      xyz="-0.01844 0 -0.052"
      rpy="1.5708 0.7854 0" />
    <parent
      link="LM_thigh" />
    <child
      link="LM_calf" />
    <axis
      xyz="0 0 1" />
    <limit
      lower="-5.236"
      upper="5.236"
      effort="0"
      velocity="0" />
  </joint>
  <link
    name="LM_foot">
    <inertial>
      <origin
        xyz="0.0189834134494404 -0.033264933187588 -0.000415814504580459"
        rpy="0 0 0" />
      <mass
        value="0.0652326387878093" />
      <inertia
        ixx="1.73083835690446E-05"
        ixy="5.85844794145788E-06"
        ixz="-1.4999729010903E-09"
        iyy="1.87949440011586E-05"
        iyz="-1.91009992628101E-07"
        izz="2.59541243064155E-05" />
    </inertial>
    <visual>
      <origin
        xyz="0 0 0"
        rpy="0 0 0" />
      <geometry>
        <mesh
          filename="package://ASSY_phantom_urdf/meshes/LM_foot.STL" />
      </geometry>
      <material
        name="">
        <color
          rgba="0.752941176470588 0.752941176470588 0.752941176470588 1" />
      </material>
    </visual>
    <collision>
      <origin
        xyz="0 0 0"
        rpy="0 0 0" />
      <geometry>
        <mesh
          filename="package://ASSY_phantom_urdf/meshes/LM_foot.STL" />
      </geometry>
    </collision>
  </link>
  <joint
    name="LM3"
    type="revolute">
    <origin
      xyz="0.014589 -0.06443 0"
      rpy="0 0 1.3658" />
    <parent
      link="LM_calf" />
    <child
      link="LM_foot" />
    <axis
      xyz="0 0 1" />
    <limit
      lower="-5.236"
      upper="5.236"
      effort="0"
      velocity="0" />
  </joint>
  <link
    name="LB_thigh">
    <inertial>
      <origin
        xyz="-0.0194026504263946 0.000962648415415969 -0.0260087497830563"
        rpy="0 0 0" />
      <mass
        value="0.0187184822855231" />
      <inertia
        ixx="4.58328060295333E-06"
        ixy="-1.45214380689525E-12"
        ixz="9.54272944654011E-11"
        iyy="4.58328035716506E-06"
        iyz="8.99626362026522E-11"
        izz="5.84140443768985E-06" />
    </inertial>
    <visual>
      <origin
        xyz="0 0 0"
        rpy="0 0 0" />
      <geometry>
        <mesh
          filename="package://ASSY_phantom_urdf/meshes/LB_thigh.STL" />
      </geometry>
      <material
        name="">
        <color
          rgba="0.752941176470588 0.752941176470588 0.752941176470588 1" />
      </material>
    </visual>
    <collision>
      <origin
        xyz="0 0 0"
        rpy="0 0 0" />
      <geometry>
        <mesh
          filename="package://ASSY_phantom_urdf/meshes/LB_thigh.STL" />
      </geometry>
    </collision>
  </link>
  <joint
    name="LB1"
    type="revolute">
    <origin
      xyz="0.06091 0 -0.12191"
      rpy="0.7854 0 -1.5708" />
    <parent
      link="torso" />
    <child
      link="LB_thigh" />
    <axis
      xyz="1 0 0" />
    <limit
      lower="-5.236"
      upper="5.236"
      effort="0"
      velocity="0" />
  </joint>
  <link
    name="LB_calf">
    <inertial>
      <origin
        xyz="0.00102679192339997 -0.0223107697760034 -0.000736289104140059"
        rpy="0 0 0" />
      <mass
        value="0.0551626378910084" />
      <inertia
        ixx="1.54903467359071E-05"
        ixy="2.95997531578752E-07"
        ixz="-1.48897181529104E-09"
        iyy="1.05260916908926E-05"
        iyz="-1.91029456445046E-07"
        izz="1.16899614331516E-05" />
    </inertial>
    <visual>
      <origin
        xyz="0 0 0"
        rpy="0 0 0" />
      <geometry>
        <mesh
          filename="package://ASSY_phantom_urdf/meshes/LB_calf.STL" />
      </geometry>
      <material
        name="">
        <color
          rgba="0.752941176470588 0.752941176470588 0.752941176470588 1" />
      </material>
    </visual>
    <collision>
      <origin
        xyz="0 0 0"
        rpy="0 0 0" />
      <geometry>
        <mesh
          filename="package://ASSY_phantom_urdf/meshes/LB_calf.STL" />
      </geometry>
    </collision>
  </link>
  <joint
    name="LB2"
    type="revolute">
    <origin
      xyz="-0.01844 0 -0.052"
      rpy="1.5708 0.7854 0" />
    <parent
      link="LB_thigh" />
    <child
      link="LB_calf" />
    <axis
      xyz="0 0 1" />
    <limit
      lower="-5.236"
      upper="5.236"
      effort="0"
      velocity="0" />
  </joint>
  <link
    name="LB_foot">
    <inertial>
      <origin
        xyz="0.0189834041321391 -0.0332649280290424 -0.000415814389983629"
        rpy="0 0 0" />
      <mass
        value="0.0652326466286265" />
      <inertia
        ixx="1.73083837683577E-05"
        ixy="5.85844793814884E-06"
        ixz="-1.49998074540365E-09"
        iyy="1.87949439630518E-05"
        iyz="-1.91009991926193E-07"
        izz="2.59541244072091E-05" />
    </inertial>
    <visual>
      <origin
        xyz="0 0 0"
        rpy="0 0 0" />
      <geometry>
        <mesh
          filename="package://ASSY_phantom_urdf/meshes/LB_foot.STL" />
      </geometry>
      <material
        name="">
        <color
          rgba="0.752941176470588 0.752941176470588 0.752941176470588 1" />
      </material>
    </visual>
    <collision>
      <origin
        xyz="0 0 0"
        rpy="0 0 0" />
      <geometry>
        <mesh
          filename="package://ASSY_phantom_urdf/meshes/LB_foot.STL" />
      </geometry>
    </collision>
  </link>
  <joint
    name="LB3"
    type="revolute">
    <origin
      xyz="0.014589 -0.06443 0"
      rpy="0 0 1.3658" />
    <parent
      link="LB_calf" />
    <child
      link="LB_foot" />
    <axis
      xyz="0 0 1" />
    <limit
      lower="-5.236"
      upper="5.236"
      effort="0"
      velocity="0" />
  </joint>
  <link
    name="RF_thigh">
    <inertial>
      <origin
        xyz="-0.0194027231911689 0.000962720771382118 0.0260087651240974"
        rpy="0 0 0" />
      <mass
        value="0.0187187999416221" />
      <inertia
        ixx="4.58336747949758E-06"
        ixy="-1.38095725082366E-11"
        ixz="-1.50188775491737E-10"
        iyy="4.58336713269771E-06"
        iyz="-1.46826574790879E-10"
        izz="5.84152341451725E-06" />
    </inertial>
    <visual>
      <origin
        xyz="0 0 0"
        rpy="0 0 0" />
      <geometry>
        <mesh
          filename="package://ASSY_phantom_urdf/meshes/RF_thigh.STL" />
      </geometry>
      <material
        name="">
        <color
          rgba="0.752941176470588 0.752941176470588 0.752941176470588 1" />
      </material>
    </visual>
    <collision>
      <origin
        xyz="0 0 0"
        rpy="0 0 0" />
      <geometry>
        <mesh
          filename="package://ASSY_phantom_urdf/meshes/RF_thigh.STL" />
      </geometry>
    </collision>
  </link>
  <joint
    name="RF1"
    type="revolute">
    <origin
      xyz="-0.06091 0 0.12191"
      rpy="0.7854 0 -1.5708" />
    <parent
      link="torso" />
    <child
      link="RF_thigh" />
    <axis
      xyz="1 0 0" />
    <limit
      lower="-5.236"
      upper="5.236"
      effort="0"
      velocity="0" />
  </joint>
  <link
    name="RF_calf">
    <inertial>
      <origin
        xyz="0.00102680024360452 -0.0223108610345546 0.000736290423570971"
        rpy="0 0 0" />
      <mass
        value="0.0551628381598268" />
      <inertia
        ixx="1.54904289071492E-05"
        ixy="2.96004655684944E-07"
        ixz="1.4604886624265E-09"
        iyy="1.05261447920822E-05"
        iyz="1.91036737859883E-07"
        izz="1.16899750550889E-05" />
    </inertial>
    <visual>
      <origin
        xyz="0 0 0"
        rpy="0 0 0" />
      <geometry>
        <mesh
          filename="package://ASSY_phantom_urdf/meshes/RF_calf.STL" />
      </geometry>
      <material
        name="">
        <color
          rgba="0.752941176470588 0.752941176470588 0.752941176470588 1" />
      </material>
    </visual>
    <collision>
      <origin
        xyz="0 0 0"
        rpy="0 0 0" />
      <geometry>
        <mesh
          filename="package://ASSY_phantom_urdf/meshes/RF_calf.STL" />
      </geometry>
    </collision>
  </link>
  <joint
    name="RF2"
    type="revolute">
    <origin
      xyz="-0.01844 0 0.052"
      rpy="-1.5708 -0.7854 0" />
    <parent
      link="RF_thigh" />
    <child
      link="RF_calf" />
    <axis
      xyz="0 0 1" />
    <limit
      lower="-5.236"
      upper="5.236"
      effort="0"
      velocity="0" />
  </joint>
  <link
    name="RF_foot">
    <inertial>
      <origin
        xyz="0.018373389650663 -0.0328919722792271 0.000415796603429955"
        rpy="0 0 0" />
      <mass
        value="0.0652327270508921" />
      <inertia
        ixx="1.73083949891202E-05"
        ixy="5.85844817413531E-06"
        ixz="1.50084219603285E-09"
        iyy="1.8794961357601E-05"
        iyz="1.91005450888028E-07"
        izz="2.59541152159503E-05" />
    </inertial>
    <visual>
      <origin
        xyz="0 0 0"
        rpy="0 0 0" />
      <geometry>
        <mesh
          filename="package://ASSY_phantom_urdf/meshes/RF_foot.STL" />
      </geometry>
      <material
        name="">
        <color
          rgba="0.752941176470588 0.752941176470588 0.752941176470588 1" />
      </material>
    </visual>
    <collision>
      <origin
        xyz="0 0 0"
        rpy="0 0 0" />
      <geometry>
        <mesh
          filename="package://ASSY_phantom_urdf/meshes/RF_foot.STL" />
      </geometry>
    </collision>
  </link>
  <joint
    name="RF3"
    type="revolute">
    <origin
      xyz="0.014589 -0.06443 0"
      rpy="0 0 1.3658" />
    <parent
      link="RF_calf" />
    <child
      link="RF_foot" />
    <axis
      xyz="0 0 1" />
    <limit
      lower="-5.236"
      upper="5.236"
      effort="0"
      velocity="0" />
  </joint>
  <link
    name="RM_thigh">
    <inertial>
      <origin
        xyz="-0.0194027237249261 0.00096272374256581 0.0260088003580916"
        rpy="0 0 0" />
      <mass
        value="0.0187188019506362" />
      <inertia
        ixx="4.58336504964393E-06"
        ixy="-1.38919554687681E-11"
        ixz="-1.48345216924498E-10"
        iyy="4.58336504964393E-06"
        iyz="-1.48346245087308E-10"
        izz="5.84152380154398E-06" />
    </inertial>
    <visual>
      <origin
        xyz="0 0 0"
        rpy="0 0 0" />
      <geometry>
        <mesh
          filename="package://ASSY_phantom_urdf/meshes/RM_thigh.STL" />
      </geometry>
      <material
        name="">
        <color
          rgba="0.752941176470588 0.752941176470588 0.752941176470588 1" />
      </material>
    </visual>
    <collision>
      <origin
        xyz="0 0 0"
        rpy="0 0 0" />
      <geometry>
        <mesh
          filename="package://ASSY_phantom_urdf/meshes/RM_thigh.STL" />
      </geometry>
    </collision>
  </link>
  <joint
    name="RM1"
    type="revolute">
    <origin
      xyz="-0.1035 0 0"
      rpy="1.5708 0 -1.5708" />
    <parent
      link="torso" />
    <child
      link="RM_thigh" />
    <axis
      xyz="1 0 0" />
    <limit
      lower="-5.236"
      upper="5.236"
      effort="0"
      velocity="0" />
  </joint>
  <link
    name="RM_calf">
    <inertial>
      <origin
        xyz="0.00102680218372297 -0.0223108633657772 0.000736291324398924"
        rpy="0 0 0" />
      <mass
        value="0.0551628383199495" />
      <inertia
        ixx="1.54904303401299E-05"
        ixy="2.96006272123672E-07"
        ixz="1.46127435683613E-09"
        iyy="1.05261466940388E-05"
        iyz="1.91035908075712E-07"
        izz="1.16899783369022E-05" />
    </inertial>
    <visual>
      <origin
        xyz="0 0 0"
        rpy="0 0 0" />
      <geometry>
        <mesh
          filename="package://ASSY_phantom_urdf/meshes/RM_calf.STL" />
      </geometry>
      <material
        name="">
        <color
          rgba="0.752941176470588 0.752941176470588 0.752941176470588 1" />
      </material>
    </visual>
    <collision>
      <origin
        xyz="0 0 0"
        rpy="0 0 0" />
      <geometry>
        <mesh
          filename="package://ASSY_phantom_urdf/meshes/RM_calf.STL" />
      </geometry>
    </collision>
  </link>
  <joint
    name="RM2"
    type="revolute">
    <origin
      xyz="-0.01844 0 0.052"
      rpy="-1.5708 -0.7854 0" />
    <parent
      link="RM_thigh" />
    <child
      link="RM_calf" />
    <axis
      xyz="0 0 1" />
    <limit
      lower="-5.236"
      upper="5.236"
      effort="0"
      velocity="0" />
  </joint>
  <link
    name="RM_foot">
    <inertial>
      <origin
        xyz="0.0183733977645456 -0.0328919764830271 0.000415796418803333"
        rpy="0 0 0" />
      <mass
        value="0.0652327208733654" />
      <inertia
        ixx="1.73083948003673E-05"
        ixy="5.85844817760194E-06"
        ixz="1.50083690920487E-09"
        iyy="1.87949614300931E-05"
        iyz="1.910054381263E-07"
        izz="2.59541150881639E-05" />
    </inertial>
    <visual>
      <origin
        xyz="0 0 0"
        rpy="0 0 0" />
      <geometry>
        <mesh
          filename="package://ASSY_phantom_urdf/meshes/RM_foot.STL" />
      </geometry>
      <material
        name="">
        <color
          rgba="0.752941176470588 0.752941176470588 0.752941176470588 1" />
      </material>
    </visual>
    <collision>
      <origin
        xyz="0 0 0"
        rpy="0 0 0" />
      <geometry>
        <mesh
          filename="package://ASSY_phantom_urdf/meshes/RM_foot.STL" />
      </geometry>
    </collision>
  </link>
  <joint
    name="RM3"
    type="revolute">
    <origin
      xyz="0.014589 -0.06443 0"
      rpy="0 0 1.3658" />
    <parent
      link="RM_calf" />
    <child
      link="RM_foot" />
    <axis
      xyz="0 0 1" />
    <limit
      lower="-5.236"
      upper="5.236"
      effort="0"
      velocity="0" />
  </joint>
  <link
    name="RB_thigh">
    <inertial>
      <origin
        xyz="-0.0194027231911689 0.00096272077138216 0.0260087651240974"
        rpy="0 0 0" />
      <mass
        value="0.018718799941622" />
      <inertia
        ixx="4.58336747949757E-06"
        ixy="-1.38095725086186E-11"
        ixz="-1.50188775489242E-10"
        iyy="4.5833671326977E-06"
        iyz="-1.46826574781985E-10"
        izz="5.84152341451724E-06" />
    </inertial>
    <visual>
      <origin
        xyz="0 0 0"
        rpy="0 0 0" />
      <geometry>
        <mesh
          filename="package://ASSY_phantom_urdf/meshes/RB_thigh.STL" />
      </geometry>
      <material
        name="">
        <color
          rgba="0.752941176470588 0.752941176470588 0.752941176470588 1" />
      </material>
    </visual>
    <collision>
      <origin
        xyz="0 0 0"
        rpy="0 0 0" />
      <geometry>
        <mesh
          filename="package://ASSY_phantom_urdf/meshes/RB_thigh.STL" />
      </geometry>
    </collision>
  </link>
  <joint
    name="RB1"
    type="revolute">
    <origin
      xyz="-0.06091 0 -0.12191"
      rpy="2.3562 0 -1.5708" />
    <parent
      link="torso" />
    <child
      link="RB_thigh" />
    <axis
      xyz="1 0 0" />
    <limit
      lower="-5.236"
      upper="5.236"
      effort="0"
      velocity="0" />
  </joint>
  <link
    name="RB_calf">
    <inertial>
      <origin
        xyz="0.00102680024360452 -0.0223108610345546 0.000736290423570957"
        rpy="0 0 0" />
      <mass
        value="0.0551628381598268" />
      <inertia
        ixx="1.54904289071492E-05"
        ixy="2.96004655684952E-07"
        ixz="1.46048866241718E-09"
        iyy="1.05261447920822E-05"
        iyz="1.91036737859886E-07"
        izz="1.16899750550889E-05" />
    </inertial>
    <visual>
      <origin
        xyz="0 0 0"
        rpy="0 0 0" />
      <geometry>
        <mesh
          filename="package://ASSY_phantom_urdf/meshes/RB_calf.STL" />
      </geometry>
      <material
        name="">
        <color
          rgba="0.752941176470588 0.752941176470588 0.752941176470588 1" />
      </material>
    </visual>
    <collision>
      <origin
        xyz="0 0 0"
        rpy="0 0 0" />
      <geometry>
        <mesh
          filename="package://ASSY_phantom_urdf/meshes/RB_calf.STL" />
      </geometry>
    </collision>
  </link>
  <joint
    name="RB2"
    type="revolute">
    <origin
      xyz="-0.01844 0 0.052"
      rpy="-1.5708 -0.7854 0" />
    <parent
      link="RB_thigh" />
    <child
      link="RB_calf" />
    <axis
      xyz="0 0 1" />
    <limit
      lower="-5.236"
      upper="5.236"
      effort="0"
      velocity="0" />
  </joint>
  <link
    name="RB_foot">
    <inertial>
      <origin
        xyz="0.0183733896506632 -0.032891972279227 0.000415796603430107"
        rpy="0 0 0" />
      <mass
        value="0.0652327270508919" />
      <inertia
        ixx="1.73083949891201E-05"
        ixy="5.8584481741353E-06"
        ixz="1.50084219601421E-09"
        iyy="1.87949613576009E-05"
        iyz="1.91005450888034E-07"
        izz="2.59541152159502E-05" />
    </inertial>
    <visual>
      <origin
        xyz="0 0 0"
        rpy="0 0 0" />
      <geometry>
        <mesh
          filename="package://ASSY_phantom_urdf/meshes/RB_foot.STL" />
      </geometry>
      <material
        name="">
        <color
          rgba="0.752941176470588 0.752941176470588 0.752941176470588 1" />
      </material>
    </visual>
    <collision>
      <origin
        xyz="0 0 0"
        rpy="0 0 0" />
      <geometry>
        <mesh
          filename="package://ASSY_phantom_urdf/meshes/RB_foot.STL" />
      </geometry>
    </collision>
  </link>
  <joint
    name="RB3"
    type="revolute">
    <origin
      xyz="0.014589 -0.06443 0"
      rpy="0 0 1.3658" />
    <parent
      link="RB_calf" />
    <child
      link="RB_foot" />
    <axis
      xyz="0 0 1" />
    <limit
      lower="-5.236"
      upper="5.236"
      effort="0"
      velocity="0" />
  </joint>
</robot>
